<!DOCTYPE html>
<html>
	<head>
		<meta charset="UTF-8">
		<title>指定发生错误时的回调函数</title>
	</head>
	<body>
		<h1>指定发生错误时的回调函数</h1>
		<p>Promise.prototype.catch方法是.then(null, rejection)的别名，用于指定发生错误时的回调函数</p>
		<script>
			getJSON("/post.json").then(function(posts){
				//...
			}).catch(function(error) {
				// 处理前一个回调函数运行时发生的错误
				document.write('发生错误！', error);
			});
		</script>
		<p>getJSON方法返回一个Promise对象，如果该对象状态变为Resolved，则会调用then方法指定的回调函数</p>
		<p>如果异步操作抛出错误，状态就会变为Rejected，就会调用catch方法指定的回调函数，处理这个错误</p>
		<script>
			var promise = new Promise(function(reslove, reject) {
				throw new Error('test')
			});
			promise.catch(function(error) {
				document.write(errror);
			})
		</script>
		<p>Promise抛出一个错误，就被catch方法指定的回调函数捕获</p>
		<p>Promise对象的错误具有“冒泡”性质，会一直向后传递，直到被捕获为止。也就是说，错误总是会被下一个catch语句捕获</p>
		<script>
			getJSON("/post/1.json").then(function(post) {
				return getJSON(post.commentURL);
			}).then(function(comments) {
				//some code
			}).catch(function(error) {
				//处理前面三个Promise产生的错误
			});
		</script>
		<p>上面代码中，一共有三个Promise对象：一个由getJSON产生，两个由then产生。它们之中任何一个抛出的错误，都会被最后一个catch捕获</p>
	</body>
</html>
